Workbook

Sheet Người 1
A1: Nhóm | B1: title | C1: reviewsCount (max 1035) | D1: totalScore | E1: street | F1: state | G1: searchString | H1: url | I1: reviewsCount gốc
A2: Nhóm 1 | B2: Pizza 4P's Hoang Van Thu | C2: 1035 | D2: 4.8 | E2: quan, 8 Hoàng Văn Thụ | F2: Hai Chau, Da Nang | G2: Quán pizza | H2: https://www.google.com/maps/search/?api=1&query=Pizza%204P's%20Hoang%20Van%20Thu&query_place_id=ChIJqUAP38wZQjERRq1t5kQSTdI | I2: 17061
A3: Nhóm 1 | B3: Nhà hàng Madame Lân | C3: 1035 | D3: 4.3 | E3: 04 Bạch Đằng | F3: Hải Châu, Đà Nẵng | G3: Nhà hàng | H3: https://www.google.com/maps/search/?api=1&query=Nh%C3%A0%20h%C3%A0ng%20Madame%20L%C3%A2n&query_place_id=ChIJe0VNzjEYQjERImNbpnRF9cI | I3: 14304
A4: Nhóm 1 | B4: Pizza 4P's indochina Đà Nẵng | C4: 1035 | D4: 4.9 | E4: 74 Bạch Đằng | F4: Hải Châu, Đà Nẵng | G4: Quán ăn tối | H4: https://www.google.com/maps/search/?api=1&query=Pizza%204P's%20indochina%20%C4%90%C3%A0%20N%E1%BA%B5ng&query_place_id=ChIJCe8L9TwZQjERLsIy5OgdG28 | I4: 13724
A5: Nhóm 1 | B5: Bánh Xèo Bà Dưỡng | C5: 1035 | D5: 4.3 | E5: 280/23 Hoàng Diệu | F5: Hải Châu, Đà Nẵng | G5: restaurant | H5: https://www.google.com/maps/search/?api=1&query=B%C3%A1nh%20X%C3%A8o%20B%C3%A0%20D%C6%B0%E1%BB%A1ng&query_place_id=ChIJrSiIJ8oZQjERn2-PvhzOCuU | I5: 10812
A6: Nhóm 1 | B6: XÓM MỚI GARDEN | C6: 1035 | D6: 4.9 | E6: 222 Trần Phú | F6: Hải Châu, Đà Nẵng | G6: Nhà hàng Hàn Quốc | H6: https://www.google.com/maps/search/?api=1&query=X%C3%93M%20M%E1%BB%9AI%20GARDEN&query_place_id=ChIJjaiK7LgZQjERSQvPDP9gnVQ | I6: 10255
A7: Nhóm 1 | B7: Cộng Cà Phê | C7: 1035 | D7: 4.1 | E7: 98-96 Bạch Đằng | F7: Hai Chau, Da Nang | G7: Quán cà phê | H7: https://www.google.com/maps/search/?api=1&query=C%E1%BB%99ng%20C%C3%A0%20Ph%C3%AA&query_place_id=ChIJi0bpGjIYQjERRodYRF89PH8 | I7: 10196
A8: Nhóm 1 | B8: Ăn Thôi | C8: 1035 | D8: 4.8 | E8: 114 Bạch Đằng | F8: Hải Châu, Đà Nẵng | G8: Nhà hàng Việt Nam | H8: https://www.google.com/maps/search/?api=1&query=%C4%82n%20Th%C3%B4i&query_place_id=ChIJYVPRIUkZQjERH-v3yrc3lt0 | I8: 8195
A9: Nhóm 1 | B9: Bún thịt nướng Bà Trai | C9: 744 | D9: 4.2 | E9: 194 Đống Đa | F9: Hải Châu, Đà Nẵng | G9: Quán bún | H9: https://www.google.com/maps/search/?api=1&query=B%C3%BAn%20th%E1%BB%8Bt%20n%C6%B0%E1%BB%9Bng%20B%C3%A0%20Trai&query_place_id=ChIJ1a0JATkYQjERRlklbLmP9rg | I9: 744
A10: Nhóm 1 | B10: Bánh Mì Quốc Doanh Bà Đức | C10: 11 | D10: 4.3 | E10: 51 Phạm Hồng Thái | F10: Hải Châu, Đà Nẵng | G10: Quán mỳ | H10: https://www.google.com/maps/search/?api=1&query=B%C3%A1nh%20M%C3%AC%20Qu%E1%BB%91c%20Doanh%20B%C3%A0%20%C4%90%E1%BB%A9c&query_place_id=ChIJgfgCUgAZQjERwkjkVnuEjcg | I10: 11
B11: Tổng nhóm | C11: =SUM(C2:C10) -> 8000
A13: Nhóm 8 | B13: Nhà Hàng Phì Lũ 1 | C13: 1035 | D13: 4.4 | E13: 225 Nguyễn Chí Thanh | F13: Hải Châu, Đà Nẵng | G13: Nhà hàng Trung Quốc | H13: https://www.google.com/maps/search/?api=1&query=Nh%C3%A0%20H%C3%A0ng%20Ph%C3%AC%20L%C5%A9%201&query_place_id=ChIJw-zBdzMYQjERNlbwU3SwOdc | I13: 1871
A14: Nhóm 8 | B14: Thai Market Restaurant - Trần Quốc Toản | C14: 1035 | D14: 4.5 | E14: 04 Trần Quốc Toản | F14: Hải Châu, Đà Nẵng | G14: Quán ăn tối | H14: https://www.google.com/maps/search/?api=1&query=Thai%20Market%20Restaurant%20-%20Tr%E1%BA%A7n%20Qu%E1%BB%91c%20To%E1%BA%A3n&query_place_id=ChIJKVfX8jIYQjER3mM7bO2HeqI | I14: 1859
A15: Nhóm 8 | B15: Highlands Coffee VTV8 | C15: 1035 | D15: 4.4 | E15: 258 Bạch Đằng | F15: Hai Chau, Da Nang | G15: Quán bar | H15: https://www.google.com/maps/search/?api=1&query=Highlands%20Coffee%20VTV8&query_place_id=ChIJr7zJYAkZQjERA0lYwQ-BpOk | I15: 1850
A16: Nhóm 8 | B16: Jollibee Đống Đa | C16: 1035 | D16: 4.7 | E16: 254 Đống Đa | F16: Hai Chau, Da Nang | G16: Tiệm bánh | H16: https://www.google.com/maps/search/?api=1&query=Jollibee%20%C4%90%E1%BB%91ng%20%C4%90a&query_place_id=ChIJRUl1tCoZQjER7SLSqKcTVgk | I16: 1777
A17: Nhóm 8 | B17: EZI - Đậm Đà Nẵng - 388 Đống Đa | C17: 1035 | D17: 4.6 | E17: 388 Đống Đa | F17: Hai Chau, Da Nang | G17: Quán trà sữa | H17: https://www.google.com/maps/search/?api=1&query=EZI%20-%20%C4%90%E1%BA%ADm%20%C4%90%C3%A0%20N%E1%BA%B5ng%20-%20388%20%C4%90%E1%BB%91ng%20%C4%90a&query_place_id=ChIJf-GHukcYQjERyQoRvi6SumQ | I17: 1732
A18: Nhóm 8 | B18: Phở Thìn Đà Nẵng | C18: 1035 | D18: 4.3 | E18: 60 Pasteur | F18: Hai Chau, Da Nang | G18: Quán nhậu | H18: https://www.google.com/maps/search/?api=1&query=Ph%E1%BB%9F%20Th%C3%ACn%20%C4%90%C3%A0%20N%E1%BA%B5ng&query_place_id=ChIJsRRKFxIZQjEReyTCrVbRXTs | I18: 1724
A19: Nhóm 8 | B19: Kết High | C19: 1035 | D19: 4.9 | E19: 200 Bạch Đằng | F19: Hai Chau, Da Nang | G19: Cocktail bar | H19: https://www.google.com/maps/search/?api=1&query=K%E1%BA%BFt%20High&query_place_id=ChIJh3XZqZgZQjERm2fg63ZDaRI | I19: 1658
A20: Nhóm 8 | B20: Túc Tắc Tea Đà Nẵng - Lê Đình Dương | C20: 714 | D20: 4.6 | E20: 70 Lê Đình Dương | F20: Hai Chau, Da Nang | G20: Trà sữa | H20: https://www.google.com/maps/search/?api=1&query=T%C3%BAc%20T%E1%BA%AFc%20Tea%20%C4%90%C3%A0%20N%E1%BA%B5ng%20-%20L%C3%AA%20%C4%90%C3%ACnh%20D%C6%B0%C6%A1ng&query_place_id=ChIJq2mJuZcZQjER2yeL4uflyxw | I20: 714
A21: Nhóm 8 | B21: Quán Dốc Sông Hàn | C21: 41 | D21: 5 | E21: 1b Lê Duẩn | F21: Hai Chau, Da Nang | G21: Quán bar | H21: https://www.google.com/maps/search/?api=1&query=Qu%C3%A1n%20D%E1%BB%91c%20S%C3%B4ng%20H%C3%A0n&query_place_id=ChIJuVYeSD4ZQjER1Tt9FFmhCV8 | I21: 41
B22: Tổng nhóm | C22: =SUM(C13:C21) -> 8000
A24: Nhóm 9 | B24: Cơm Tấm Đây | C24: 1035 | D24: 4.7 | E24: 5 Phạm Phú Thứ | F24: Hải Châu, Đà Nẵng | G24: Nhà hàng Việt Nam | H24: https://www.google.com/maps/search/?api=1&query=C%C6%A1m%20T%E1%BA%A5m%20%C4%90%C3%A2y&query_place_id=ChIJDW31iLoZQjERquS25NUtGw0 | I24: 1643
A25: Nhóm 9 | B25: Limoncello | C25: 1035 | D25: 4.5 | E25: 212 Trần Phú | F25: Hải Châu, Đà Nẵng | G25: Quán ăn tối | H25: https://www.google.com/maps/search/?api=1&query=Limoncello&query_place_id=ChIJMy-k-jIYQjERyab8z9yo1lU | I25: 1642
A26: Nhóm 9 | B26: I love Bánh mì 아이러브반미 | C26: 1035 | D26: 4.3 | E26: 100 Trần Phú | F26: Hải Châu, Đà Nẵng | G26: Quán phở | H26: https://www.google.com/maps/search/?api=1&query=I%20love%20B%C3%A1nh%20m%C3%AC%20%EC%95%84%EC%9D%B4%EB%9F%AC%EB%B8%8C%EB%B0%98%EB%AF%B8&query_place_id=ChIJkzlsHOUZQjERHQgzrQC-kG4 | I26: 1639
A27: Nhóm 9 | B27: Quán Huế Ngon | C27: 1035 | D27: 4.1 | E27: 65 Trần Quốc Toản | F27: Hải Châu, Đà Nẵng | G27: Nhà hàng hải sản | H27: https://www.google.com/maps/search/?api=1&query=Qu%C3%A1n%20Hu%E1%BA%BF%20Ngon&query_place_id=ChIJCXHPczMYQjERWvCLF3Hu_CY | I27: 1626
A28: Nhóm 9 | B28: IZAKAYA IDATEN | C28: 1035 | D28: 4.9 | E28: 32 Thái Phiên | F28: Hải Châu, Đà Nẵng | G28: Quán ăn tối | H28: https://www.google.com/maps/search/?api=1&query=IZAKAYA%20IDATEN&query_place_id=ChIJ0aAaX1YZQjERsrLCQVCoP74 | I28: 1619
A29: Nhóm 9 | B29: Phở Cù Hà Nội | C29: 1035 | D29: 4.6 | E29: 05 Trần Quốc Toản | F29: Hải Châu, Đà Nẵng | G29: Quán phở | H29: https://www.google.com/maps/search/?api=1&query=Ph%E1%BB%9F%20C%C3%B9%20H%C3%A0%20N%E1%BB%99i&query_place_id=ChIJZZV83B0ZQjER91WpMAjcoyk | I29: 1609
A30: Nhóm 9 | B30: Trình cà phê - VTV8 | C30: 1035 | D30: 4.8 | E30: 256 Bạch Đằng | F30: Hai Chau, Da Nang | G30: Quán cà phê | H30: https://www.google.com/maps/search/?api=1&query=Tr%C3%ACnh%20c%C3%A0%20ph%C3%AA%20-%20VTV8&query_place_id=ChIJayh2YEYZQjER3N9LNQu3nRI | I30: 1584
A31: Nhóm 9 | B31: Cửa Ngõ Café – Cửa Hàng Số 2 | C31: 713 | D31: 4.5 | E31: 102 Nguyễn Thị Minh Khai | F31: Hai Chau, Da Nang | G31: Quán sinh tố | H31: https://www.google.com/maps/search/?api=1&query=C%E1%BB%ADa%20Ng%C3%B5%20Caf%C3%A9%20%E2%80%93%20C%E1%BB%ADa%20H%C3%A0ng%20S%E1%BB%91%202&query_place_id=ChIJz2VlXIAZQjER9VRmwBZiBLI | I31: 713
A32: Nhóm 9 | B32: Quán ăn Tuấn Trọc | C32: 42 | D32: 5 | E32: 168 Đống Đa | F32: Hải Châu, Đà Nẵng | G32: Quán ăn | H32: https://www.google.com/maps/search/?api=1&query=Qu%C3%A1n%20%C4%83n%20Tu%E1%BA%A5n%20Tr%E1%BB%8Dc&query_place_id=ChIJf2o2WwAZQjERVLq7ZehzTCY | I32: 42
B33: Tổng nhóm | C33: =SUM(C24:C32) -> 8000
A35: Nhóm 16 | B35: Nhà hàng Làn Gió | C35: 1035 | D35: 4.7 | E35: 169 Trần Phú | F35: Hải Châu, Đà Nẵng | G35: Nhà hàng buffet | H35: https://www.google.com/maps/search/?api=1&query=Nh%C3%A0%20h%C3%A0ng%20L%C3%A0n%20Gi%C3%B3&query_place_id=ChIJNRSpo9EZQjERliMnRlTXtFc | I35: 1246
A36: Nhóm 16 | B36: Quán Cô Hồng - Gỏi Cá Nam Ô | C36: 1035 | D36: 4.5 | E36: 38 Lê Hồng Phong | F36: Hải Châu, Đà Nẵng | G36: Nhà hàng hải sản | H36: https://www.google.com/maps/search/?api=1&query=Qu%C3%A1n%20C%C3%B4%20H%E1%BB%93ng%20-%20G%E1%BB%8Fi%20C%C3%A1%20Nam%20%C3%94&query_place_id=ChIJQ7Wm3ssZQjERC5aR2l8cnno | I36: 1244
A37: Nhóm 16 | B37: Alluvia Chocolate 172 Tran Phu | C37: 1035 | D37: 5 | E37: 172 Trần Phú | F37: Hai Chau, Da Nang | G37: Tiệm bánh | H37: https://www.google.com/maps/search/?api=1&query=Alluvia%20Chocolate%20172%20Tran%20Phu&query_place_id=ChIJ-1l4aSMZQjERLwivCCHlDBU | I37: 1242
A38: Nhóm 16 | B38: Mikado Sushi Indochina Riverside Da Nang | C38: 1035 | D38: 4.6 | E38: 01 Phan Đình Phùng | F38: Hải Châu, Đà Nẵng | G38: Nhà hàng buffet | H38: https://www.google.com/maps/search/?api=1&query=Mikado%20Sushi%20Indochina%20Riverside%20Da%20Nang&query_place_id=ChIJu0MjQwAZQjER6D4wxqkxTJA | I38: 1231
A39: Nhóm 16 | B39: Gé Cafe | C39: 1035 | D39: 4.3 | E39: 24 Lê Hồng Phong | F39: Hai Chau, Da Nang | G39: Quán cà phê | H39: https://www.google.com/maps/search/?api=1&query=G%C3%A9%20Cafe&query_place_id=ChIJbdw0bPoZQjERz0BEiJv3dkY | I39: 1218
A40: Nhóm 16 | B40: Cà Phê Muối Huế 3 - NCF Trần Phú | C40: 1035 | D40: 4.6 | E40: 254 Trần Phú | F40: Hai Chau, Da Nang | G40: Quán bar | H40: https://www.google.com/maps/search/?api=1&query=C%C3%A0%20Ph%C3%AA%20Mu%E1%BB%91i%20Hu%E1%BA%BF%203%20-%20NCF%20Tr%E1%BA%A7n%20Ph%C3%BA&query_place_id=ChIJ_5NQ-bkZQjERIMvo3zh7Ipw | I40: 1213
A41: Nhóm 16 | B41: Phở Hub - Halal Vietnamese Cuisine | C41: 1035 | D41: 4.8 | E41: 181 Nguyễn Chí Thanh | F41: Hải Châu, Đà Nẵng | G41: Quán mỳ | H41: https://www.google.com/maps/search/?api=1&query=Ph%E1%BB%9F%20Hub%20-%20Halal%20Vietnamese%20Cuisine&query_place_id=ChIJU5ubXpAZQjERSVCg35N7eJA | I41: 1184
A42: Nhóm 16 | B42: Hủ Tiếu Mực | C42: 686 | D42: 4.3 | E42: 15 Lê Hồng Phong | F42: Hải Châu, Đà Nẵng | G42: Quán ăn tối | H42: https://www.google.com/maps/search/?api=1&query=H%E1%BB%A7%20Ti%E1%BA%BFu%20M%E1%BB%B1c&query_place_id=ChIJQ3mJfa8ZQjERIuvEwSIFc4E | I42: 686
A43: Nhóm 16 | B43: Quán Bà Hoành - Mỳ quảng & Bún Bò | C43: 69 | D43: 4.3 | E43: 152 Nguyễn Hoàng | F43: Thanh Khe, Da Nang | G43: Quán bánh mì | H43: https://www.google.com/maps/search/?api=1&query=Qu%C3%A1n%20B%C3%A0%20Ho%C3%A0nh%20-%20M%E1%BB%B3%20qu%E1%BA%A3ng%20%26%20B%C3%BAn%20B%C3%B2&query_place_id=ChIJacC6f7UZQjER86X3L47l_HI | I43: 69
...

Sheet Trân
A1: Nhóm | B1: title | C1: reviewsCount (max 1035) | D1: totalScore | E1: street | F1: state | G1: searchString | H1: url | I1: reviewsCount gốc
A2: Nhóm 2 | B2: Trình cà phê | C2: 1035 | D2: 4.8 | E2: 25 Phạm Hồng Thái | F2: Hai Chau, Da Nang | G2: Quán cà phê | H2: https://www.google.com/maps/search/?api=1&query=Tr%C3%ACnh%20c%C3%A0%20ph%C3%AA&query_place_id=ChIJ2eFWbrcXQjERkMR0z_5VhM0 | I2: 7814
A3: Nhóm 2 | B3: Cô Ba Phở bò | C3: 1035 | D3: 4.7 | E3: 154 Bạch Đằng | F3: Hải Châu, Đà Nẵng | G3: Quán phở | H3: https://www.google.com/maps/search/?api=1&query=C%C3%B4%20Ba%20Ph%E1%BB%9F%20b%C3%B2&query_place_id=ChIJQYGTw4MZQjER9-WZcXZUfAM | I3: 6729
A4: Nhóm 2 | B4: UGANE | C4: 1035 | D4: 4.9 | E4: 181 Trần Phú | F4: Hai Chau, Da Nang | G4: Tiệm bánh | H4: https://www.google.com/maps/search/?api=1&query=UGANE&query_place_id=ChIJlcQ5nxwZQjERKZyFr1rNcCw | I4: 6594
A5: Nhóm 2 | B5: Nhà hàng NHÀ BẾP CHỢ HÀN | C5: 1035 | D5: 4.7 | E5: 22 Hùng Vương | F5: Hải Châu, Đà Nẵng | G5: Nhà hàng | H5: https://www.google.com/maps/search/?api=1&query=Nh%C3%A0%20h%C3%A0ng%20NH%C3%80%20B%E1%BA%BEP%20CH%E1%BB%A2%20H%C3%80N&query_place_id=ChIJP1Uz6i0ZQjERfy-rpM1cGWc | I5: 5997
A6: Nhóm 2 | B6: UMEYAKI - BBQ BUFFET | C6: 1035 | D6: 4.9 | E6: 26 Quang Trung | F6: Hải Châu, Đà Nẵng | G6: Nhà hàng buffet | H6: https://www.google.com/maps/search/?api=1&query=UMEYAKI%20-%20BBQ%20BUFFET&query_place_id=ChIJi_oeVgAZQjERvZH3PK8qRLA | I6: 4789
A7: Nhóm 2 | B7: MAAZI | C7: 1035 | D7: 4.8 | E7: 264 Trần Phú | F7: Hải Châu, Đà Nẵng | G7: restaurant | H7: https://www.google.com/maps/search/?api=1&query=MAAZI&query_place_id=ChIJqaQoXYMZQjERX_QzVEAZr_Q | I7: 4721
A8: Nhóm 2 | B8: Quán Phở Hồng | C8: 1035 | D8: 4.3 | E8: 10 Lý Tự Trọng | F8: Hai Chau, Da Nang | G8: Pub | H8: https://www.google.com/maps/search/?api=1&query=Qu%C3%A1n%20Ph%E1%BB%9F%20H%E1%BB%93ng&query_place_id=ChIJ5crNSwAZQjER1FLL3WSTID8 | I8: 4706
A9: Nhóm 2 | B9: Sangha - Vegetarian Restaurant | C9: 740 | D9: 4.5 | E9: 84 Hoàng Văn Thụ | F9: Hải Châu, Đà Nẵng | G9: restaurant | H9: https://www.google.com/maps/search/?api=1&query=Sangha%20-%20Vegetarian%20Restaurant&query_place_id=ChIJqwoK1BwZQjERSG9mG5m__eI | I9: 740
A10: Nhóm 2 | B10: Adam Cafe | C10: 15 | D10: 3.5 | E10: 114 Phan Châu Trinh | F10: Hai Chau, Da Nang | G10: Quán cà phê | H10: https://www.google.com/maps/search/?api=1&query=Adam%20Cafe&query_place_id=ChIJqTXNurQZQjERWBP_4tHP6Bo | I10: 15
B11: Tổng nhóm | C11: =SUM(C2:C10) -> 8000
A13: Nhóm 7 | B13: Bánh mì Cô Tiên | C13: 1035 | D13: 4.2 | E13: Kiệt 80/10 Trần Phú | F13: Hải Châu, Đà Nẵng | G13: Quán mỳ | H13: https://www.google.com/maps/search/?api=1&query=B%C3%A1nh%20m%C3%AC%20C%C3%B4%20Ti%C3%AAn&query_place_id=ChIJvXHUrV0ZQjERoXiEbJBkSoc | I13: 2077
A14: Nhóm 7 | B14: BREWHAHA Central - Local Craft Beer House | C14: 1035 | D14: 4.6 | E14: 16 Thái Phiên | F14: Hai Chau, Da Nang | G14: Beer club | H14: https://www.google.com/maps/search/?api=1&query=BREWHAHA%20Central%20-%20Local%20Craft%20Beer%20House&query_place_id=ChIJa333v4gPQjERdo78iUdIOS0 | I14: 2008
A15: Nhóm 7 | B15: Totoro Nướng & Sushi - Quán Nướng, Sushi Đà Nẵng | C15: 1035 | D15: 4.9 | E15: 287 Nguyễn Chí Thanh | F15: Hải Châu, Đà Nẵng | G15: Quán ăn tối | H15: https://www.google.com/maps/search/?api=1&query=Totoro%20N%C6%B0%E1%BB%9Bng%20%26%20Sushi%20-%20Qu%C3%A1n%20N%C6%B0%E1%BB%9Bng%2C%20Sushi%20%C4%90%C3%A0%20N%E1%BA%B5ng&query_place_id=ChIJxZsivFIZQjERLFjdCkk-uHg | I15: 1998
A16: Nhóm 7 | B16: LUK LAK | C16: 1035 | D16: 4.6 | E16: 28 Bạch Đằng | F16: Hai Chau, Da Nang | G16: Pub | H16: https://www.google.com/maps/search/?api=1&query=LUK%20LAK&query_place_id=ChIJUWBNGo0ZQjERJDLv-2XGwe8 | I16: 1967
A17: Nhóm 7 | B17: NAM house Cafe | C17: 1035 | D17: 4.7 | E17: 15/1 Lê Hồng Phong | F17: Hai Chau, Da Nang | G17: Quán sinh tố | H17: https://www.google.com/maps/search/?api=1&query=NAM%20house%20Cafe&query_place_id=ChIJTahQxcwZQjERrNKa5emQFC4 | I17: 1945
A18: Nhóm 7 | B18: Bamboo 2 Bar | C18: 1035 | D18: 4.2 | E18: 216 Bạch Đằng | F18: Hai Chau, Da Nang | G18: Quán bar | H18: https://www.google.com/maps/search/?api=1&query=Bamboo%202%20Bar&query_place_id=ChIJXdDUwzIYQjERxDBcA0prFDo | I18: 1931
A19: Nhóm 7 | B19: Olivia's Prime Steakhouse | C19: 1035 | D19: 4.6 | E19: Indochina Mall, 74 Bach Dang, Lot G1-G4, The Ground Floor | F19: Hai Chau, Da Nang | G19: Quán bar | H19: https://www.google.com/maps/search/?api=1&query=Olivia's%20Prime%20Steakhouse&query_place_id=ChIJYxCN7iwYQjERLuz4t50uWQo | I19: 1876
A20: Nhóm 7 | B20: Ky Vat - Vietnamese Restaurant | C20: 714 | D20: 4.9 | E20: 56a Lê Hồng Phong | F20: Hải Châu, Đà Nẵng | G20: restaurant | H20: https://www.google.com/maps/search/?api=1&query=Ky%20Vat%20-%20Vietnamese%20Restaurant&query_place_id=ChIJqTxk8U0ZQjERwQn9lasjeu4 | I20: 714
A21: Nhóm 7 | B21: Đồng Tiến Bakery - Lê Đình Dương | C21: 41 | D21: 4.6 | E21: 106 Lê Đình Dương | F21: Hai Chau, Da Nang | G21: Bánh mỳ | H21: https://www.google.com/maps/search/?api=1&query=%C4%90%E1%BB%93ng%20Ti%E1%BA%BFn%20Bakery%20-%20L%C3%AA%20%C4%90%C3%ACnh%20D%C6%B0%C6%A1ng&query_place_id=ChIJZeTXMw8ZQjERlEwh2alOLPU | I21: 41
B22: Tổng nhóm | C22: =SUM(C13:C21) -> 8000
A24: Nhóm 10 | B24: Boulevard Gelato, Pastry & Coffee | C24: 1035 | D24: 4.4 | E24: 77 Trần Quốc Toản | F24: Hai Chau, Da Nang | G24: Quán kem | H24: https://www.google.com/maps/search/?api=1&query=Boulevard%20Gelato%2C%20Pastry%20%26%20Coffee&query_place_id=ChIJq8DocTMYQjERrIcBZUiEnSM | I24: 1582
A25: Nhóm 10 | B25: Gang Yu Hot Pot | C25: 1035 | D25: 4.8 | E25: 87 Yên Bái | F25: Hai Chau, Da Nang | G25: Quán nhậu | H25: https://www.google.com/maps/search/?api=1&query=Gang%20Yu%20Hot%20Pot&query_place_id=ChIJ-VaWslgZQjERwaL3uKR9fB4 | I25: 1576
A26: Nhóm 10 | B26: WONDERLUST - Coffee & Souvenir | C26: 1035 | D26: 4.5 | E26: 96 Trần Phú | F26: Hai Chau, Da Nang | G26: Quán bar | H26: https://www.google.com/maps/search/?api=1&query=WONDERLUST%20-%20Coffee%20%26%20Souvenir&query_place_id=ChIJQRIRJDIYQjER4JvYKu_Qnak | I26: 1567
A27: Nhóm 10 | B27: Út Tịch café | C27: 1035 | D27: 4.5 | E27: 73 Nguyễn Thái Học | F27: Hai Chau, Da Nang | G27: Quán bar | H27: https://www.google.com/maps/search/?api=1&query=%C3%9At%20T%E1%BB%8Bch%20caf%C3%A9&query_place_id=ChIJnedjAtoZQjERMCfdOOcOaaA | I27: 1562
A28: Nhóm 10 | B28: OQ Club | C28: 1035 | D28: 4.4 | E28: 18-20 Bạch Đằng | F28: Hai Chau, Da Nang | G28: Beer club | H28: https://www.google.com/maps/search/?api=1&query=OQ%20Club&query_place_id=ChIJAQ5_dEYZQjERFybDTm99Gzk | I28: 1555
A29: Nhóm 10 | B29: Truc Lam Vien Cafe & Restaurant | C29: 1035 | D29: 4.5 | E29: 08 Trần Quý Cáp | F29: Hai Chau, Da Nang | G29: Quán nhậu | H29: https://www.google.com/maps/search/?api=1&query=Truc%20Lam%20Vien%20Cafe%20%26%20Restaurant&query_place_id=ChIJvZBNfjEYQjERa3oF_Rc2lC8 | I29: 1549
A30: Nhóm 10 | B30: Phuc Long Coffee & Tea | C30: 1035 | D30: 4 | E30: 59-61 Nguyễn Văn Linh | F30: Hai Chau, Da Nang | G30: Quán chè | H30: https://www.google.com/maps/search/?api=1&query=Phuc%20Long%20Coffee%20%26%20Tea&query_place_id=ChIJU25zBZsZQjERw6uhD10SQgo | I30: 1544
A31: Nhóm 10 | B31: A-kopi Coffee | C31: 711 | D31: 4.7 | E31: 83 Trần Phú | F31: Hai Chau, Da Nang | G31: Quán bar | H31: https://www.google.com/maps/search/?api=1&query=A-kopi%20Coffee&query_place_id=ChIJy9o9jVAZQjERbIUGn68PeTo | I31: 711
A32: Nhóm 10 | B32: quán bò kho | C32: 44 | D32: 3.9 | E32: 144 Huỳnh Thúc Kháng | F32: Hai Chau, Da Nang | G32: Bánh mỳ | H32: https://www.google.com/maps/search/?api=1&query=qu%C3%A1n%20b%C3%B2%20kho&query_place_id=ChIJBekwwKkZQjERVVWVzAwADzs | I32: 44
B33: Tổng nhóm | C33: =SUM(C24:C32) -> 8000
A35: Nhóm 15 | B35: Nhà hàng Bếp | C35: 1035 | D35: 4.6 | E35: 17 Nguyễn Thái Học | F35: Hải Châu, Đà Nẵng | G35: Nhà hàng hải sản | H35: https://www.google.com/maps/search/?api=1&query=Nh%C3%A0%20h%C3%A0ng%20B%E1%BA%BFp&query_place_id=ChIJBW5bmIMZQjER0zjjQiukdE8 | I35: 1306
A36: Nhóm 15 | B36: Red Sky Steakhouse | C36: 1035 | D36: 4.7 | E36: 248 Trần Phú | F36: Hai Chau, Da Nang | G36: Quán bar | H36: https://www.google.com/maps/search/?api=1&query=Red%20Sky%20Steakhouse&query_place_id=ChIJf_EWJM0ZQjERbBl1k_zLzyM | I36: 1305
A37: Nhóm 15 | B37: Gong Cha Nguyễn Văn Linh | C37: 1035 | D37: 4 | E37: 1 Nguyễn Văn Linh | F37: Hai Chau, Da Nang | G37: Club | H37: https://www.google.com/maps/search/?api=1&query=Gong%20Cha%20Nguy%E1%BB%85n%20V%C4%83n%20Linh&query_place_id=ChIJh1LBe_IZQjER8mNnOVlabEc | I37: 1300
A38: Nhóm 15 | B38: TOXIC City | C38: 1035 | D38: 4.4 | E38: 62-63 Trần Văn Trứ | F38: Hoa Cuong, Da Nang | G38: Quán bar | H38: https://www.google.com/maps/search/?api=1&query=TOXIC%20City&query_place_id=ChIJ1bGBeBgZQjERS6a41QRIKuk | I38: 1285
A39: Nhóm 15 | B39: Túc Tắc Tea Đà Nẵng - Hải Phòng | C39: 1035 | D39: 4.6 | E39: 07 Hải Phòng | F39: Hai Chau, Da Nang | G39: Quán trà sữa | H39: https://www.google.com/maps/search/?api=1&query=T%C3%BAc%20T%E1%BA%AFc%20Tea%20%C4%90%C3%A0%20N%E1%BA%B5ng%20-%20H%E1%BA%A3i%20Ph%C3%B2ng&query_place_id=ChIJvx1_ReAZQjERqOgXKHC3UPE | I39: 1281
A40: Nhóm 15 | B40: S'Story Coffee & Kitchen | C40: 1035 | D40: 4.9 | E40: Huỳnh Thúc Kháng/119 Bình Hiên | F40: Hai Chau, Da Nang | G40: Rooftop bar | H40: https://www.google.com/maps/search/?api=1&query=S'Story%20Coffee%20%26%20Kitchen&query_place_id=ChIJlaQFd8IZQjERCnuZnirYstQ | I40: 1269
A41: Nhóm 15 | B41: Cơm Nhà Nội Restaurant | C41: 1035 | D41: 4.8 | E41: 50 Yên Bái | F41: Hải Châu, Đà Nẵng | G41: restaurant | H41: https://www.google.com/maps/search/?api=1&query=C%C6%A1m%20Nh%C3%A0%20N%E1%BB%99i%20Restaurant&query_place_id=ChIJ619_NQAZQjER03LN6732rkg | I41: 1265
A42: Nhóm 15 | B42: Banh Xeo CUOI Restaurant (Branch 2) - Authentic Vietnamese Cuisines | C42: 692 | D42: 4.6 | E42: 197 Trần Phú | F42: Hải Châu, Đà Nẵng | G42: Quán ăn tối | H42: https://www.google.com/maps/search/?api=1&query=Banh%20Xeo%20CUOI%20Restaurant%20(Branch%202)%20-%20Authentic%20Vietnamese%20Cuisines&query_place_id=ChIJLXKy4W8XQjEREdT0u-m_bV4 | I42: 692
A43: Nhóm 15 | B43: Metta Coffee & Ice Cream | C43: 63 | D43: 4.9 | E43: 45 Cô Giang | F43: Hai Chau, Da Nang | G43: Quán kem | H43: https://www.google.com/maps/search/?api=1&query=Metta%20Coffee%20%26%20Ice%20Cream&query_place_id=ChIJj2zJfAAZQjERSQhoH_p2PxI | I43: 63
...

Sheet Nguyên
A1: Nhóm | B1: title | C1: reviewsCount (max 1035) | D1: totalScore | E1: street | F1: state | G1: searchString | H1: url | I1: reviewsCount gốc
A2: Nhóm 3 | B2: Bánh mì Happy Bread Mì AA | C2: 1035 | D2: 4.4 | E2: 10 Hùng Vương | F2: Hai Chau, Da Nang | G2: Bánh mỳ | H2: https://www.google.com/maps/search/?api=1&query=B%C3%A1nh%20m%C3%AC%20Happy%20Bread%20M%C3%AC%20AA&query_place_id=ChIJ89mYFzIYQjERMUUvbWbrhGY | I2: 4681
A3: Nhóm 3 | B3: On The Radio | C3: 1035 | D3: 4.7 | E3: 76 Thái Phiên | F3: Hải Châu, Đà Nẵng | G3: Quán ăn tối | H3: https://www.google.com/maps/search/?api=1&query=On%20The%20Radio&query_place_id=ChIJkZi7gkcYQjERPd87DaNuhW0 | I3: 4669
A4: Nhóm 3 | B4: LoCo Restaurant - Danang Seafood Restaurant - 다낭 레스토랑 | C4: 1035 | D4: 4.8 | E4: 1C Lê Duẩn | F4: Hai Chau, Da Nang | G4: Quán nhậu | H4: https://www.google.com/maps/search/?api=1&query=LoCo%20Restaurant%20-%20Danang%20Seafood%20Restaurant%20-%20%EB%8B%A4%EB%82%AD%20%EB%A0%88%EC%8A%A4%ED%86%A0%EB%9E%91&query_place_id=ChIJH72bVncZQjERoTgax0OjZKY | I4: 4450
A5: Nhóm 3 | B5: Dookki Indochina Riveside Đà Nẵng | C5: 1035 | D5: 4.8 | E5: Indochina Riverside Towers, Tòa nhà, Trần Phú | F5: Hải Châu, Đà Nẵng | G5: Nhà hàng buffet | H5: https://www.google.com/maps/search/?api=1&query=Dookki%20Indochina%20Riveside%20%C4%90%C3%A0%20N%E1%BA%B5ng&query_place_id=ChIJd8rQNcQZQjERGI7YqR0s9Rk | I5: 3980
A6: Nhóm 3 | B6: Ramen Yushoken | C6: 1035 | D6: 4.9 | E6: 21 Hoàng Văn Thụ | F6: Hai Chau, Da Nang | G6: Quán bar | H6: https://www.google.com/maps/search/?api=1&query=Ramen%20Yushoken&query_place_id=ChIJxyPtlkUZQjERViQHYRBx6WA | I6: 3895
A7: Nhóm 3 | B7: The 1920's Lounge | C7: 1035 | D7: 4.8 | E7: 53 Trần Quốc Toản | F7: Hai Chau, Da Nang | G7: Lounge bar | H7: https://www.google.com/maps/search/?api=1&query=The%201920's%20Lounge&query_place_id=ChIJp5h-DjMYQjERTMBHOnlub0o | I7: 3803
A8: Nhóm 3 | B8: Nhà hàng Thiên Kim | C8: 1035 | D8: 4.4 | E8: 166 Bạch Đằng | F8: Hải Châu, Đà Nẵng | G8: Nhà hàng Việt Nam | H8: https://www.google.com/maps/search/?api=1&query=Nh%C3%A0%20h%C3%A0ng%20Thi%C3%AAn%20Kim&query_place_id=ChIJw1z2gkdTNDERULJnMFS92vg | I8: 3710
A9: Nhóm 3 | B9: Chè Thái NaNa | C9: 736 | D9: 4.4 | E9: 44 Nguyễn Văn Linh | F9: Hai Chau, Da Nang | G9: Pub | H9: https://www.google.com/maps/search/?api=1&query=Ch%C3%A8%20Th%C3%A1i%20NaNa&query_place_id=ChIJhUsxrssZQjERKUuhxibO6o8 | I9: 736
A10: Nhóm 3 | B10: Quán Tồ | C10: 19 | D10: 4.3 | E10: 18 Thanh Sơn | F10: Hải Châu, Đà Nẵng | G10: restaurant | H10: https://www.google.com/maps/search/?api=1&query=Qu%C3%A1n%20T%E1%BB%93&query_place_id=ChIJtWhNbgAZQjERRd5Phtr3oV8 | I10: 19
B11: Tổng nhóm | C11: =SUM(C2:C10) -> 8000
A13: Nhóm 6 | B13: Bếp Lụa vietnamese restaurant ( 볩루아 베트남식당 ) | C13: 1035 | D13: 4.8 | E13: 94 Bạch Đằng | F13: Hải Châu, Đà Nẵng | G13: Nhà hàng buffet | H13: https://www.google.com/maps/search/?api=1&query=B%E1%BA%BFp%20L%E1%BB%A5a%20vietnamese%20restaurant%20(%20%EB%B3%A9%EB%A3%A8%EC%95%84%20%EB%B2%A0%ED%8A%B8%EB%82%A8%EC%8B%9D%EB%8B%B9%20)&query_place_id=ChIJWXnKvR4ZQjER0SEJsr0_pbo | I13: 2316
A14: Nhóm 6 | B14: Cardi Pizzeria | C14: 1035 | D14: 4.8 | E14: Đ. 2 Tháng 9/76 Bình Hiên | F14: Hai Chau, Da Nang | G14: Quán pizza | H14: https://www.google.com/maps/search/?api=1&query=Cardi%20Pizzeria&query_place_id=ChIJbQZAAW8ZQjERiDUN3Ym6tlo | I14: 2246
A15: Nhóm 6 | B15: Cơm gà A Hải | C15: 1035 | D15: 4 | E15: 100 Thái Phiên | F15: Hải Châu, Đà Nẵng | G15: Quán ăn tối | H15: https://www.google.com/maps/search/?api=1&query=C%C6%A1m%20g%C3%A0%20A%20H%E1%BA%A3i&query_place_id=ChIJ6SbLpjQYQjER5qEkmTLPcuY | I15: 2204
A16: Nhóm 6 | B16: Mì Quảng 1A | C16: 1035 | D16: 4 | E16: 5 Hải Phòng | F16: Hải Châu, Đà Nẵng | G16: Quán mỳ | H16: https://www.google.com/maps/search/?api=1&query=M%C3%AC%20Qu%E1%BA%A3ng%201A&query_place_id=ChIJX-Pc1zYYQjEROyhEA-ZYJ5g | I16: 2180
A17: Nhóm 6 | B17: Chè Liên Đà Nẵng | C17: 1035 | D17: 4.1 | E17: 189 Hoàng Diệu | F17: Hai Chau, Da Nang | G17: Quán chè | H17: https://www.google.com/maps/search/?api=1&query=Ch%C3%A8%20Li%C3%AAn%20%C4%90%C3%A0%20N%E1%BA%B5ng&query_place_id=ChIJNUmsQ0gZQjERny4iUkgPNNg | I17: 2139
A18: Nhóm 6 | B18: Gordon's New York Pizza Cityside | C18: 1035 | D18: 4.9 | E18: 226 Bạch Đằng | F18: Hải Châu, Đà Nẵng | G18: restaurant | H18: https://www.google.com/maps/search/?api=1&query=Gordon's%20New%20York%20Pizza%20Cityside&query_place_id=ChIJB2N6XLQZQjERllLczI16eHA | I18: 2097
A19: Nhóm 6 | B19: Bún chả cá 109 | C19: 1035 | D19: 4.2 | E19: 109 Nguyễn Chí Thanh | F19: Hải Châu, Đà Nẵng | G19: Quán ăn sáng | H19: https://www.google.com/maps/search/?api=1&query=B%C3%BAn%20ch%E1%BA%A3%20c%C3%A1%20109&query_place_id=ChIJuRo-ujAYQjER1Zn689p6UQQ | I19: 2092
A20: Nhóm 6 | B20: 77S Chocolate - Gifts & Chocolate Vietnamese Store | C20: 716 | D20: 5 | E20: 103 Trần Phú | F20: Hai Chau, Da Nang | G20: Tiệm bánh | H20: https://www.google.com/maps/search/?api=1&query=77S%20Chocolate%20-%20Gifts%20%26%20Chocolate%20Vietnamese%20Store&query_place_id=ChIJ1VIXuoAZQjERJJakBtmw1cg | I20: 716
A21: Nhóm 6 | B21: Trieu Hop Restaurant | C21: 39 | D21: 4.7 | E21: 26 Trần Bình Trọng | F21: Hai Chau, Da Nang | G21: Quán bar | H21: https://www.google.com/maps/search/?api=1&query=Trieu%20Hop%20Restaurant&query_place_id=ChIJqT_YkzQYQjERpig10AfRPBA | I21: 39
B22: Tổng nhóm | C22: =SUM(C13:C21) -> 8000
A24: Nhóm 11 | B24: Central Players | C24: 1035 | D24: 4.6 | E24: Lô 57 Trần Văn Trứ | F24: Hòa Cường, Đà Nẵng | G24: restaurant | H24: https://www.google.com/maps/search/?api=1&query=Central%20Players&query_place_id=ChIJTYOxAeIZQjERxcNnzSYYq14 | I24: 1543
A25: Nhóm 11 | B25: Nhà hàng Mr.Anh | C25: 1035 | D25: 4.8 | E25: 340 Ông Ích Khiêm | F25: Thanh Khê, Đà Nẵng | G25: Nhà hàng | H25: https://www.google.com/maps/search/?api=1&query=Nh%C3%A0%20h%C3%A0ng%20Mr.Anh&query_place_id=ChIJV_BGLtAZQjERD9LS1cvwDwg | I25: 1539
A26: Nhóm 11 | B26: NHÀ HÀNG HỒNG NGỌC | C26: 1035 | D26: 3.6 | E26: 193 Nguyễn Chí Thanh | F26: Hải Châu, Đà Nẵng | G26: Quán ăn tối | H26: https://www.google.com/maps/search/?api=1&query=NH%C3%80%20H%C3%80NG%20H%E1%BB%92NG%20NG%E1%BB%8CC&query_place_id=ChIJEfpBJDEYQjERjBNlSpkJj78 | I26: 1534
A27: Nhóm 11 | B27: Út Tịch Café | C27: 1035 | D27: 4.5 | E27: 102 Bạch Đằng | F27: Hai Chau, Da Nang | G27: Quán cà phê | H27: https://www.google.com/maps/search/?api=1&query=%C3%9At%20T%E1%BB%8Bch%20Caf%C3%A9&query_place_id=ChIJ58vWFWAZQjERW-fhjkVfrQM | I27: 1527
A28: Nhóm 11 | B28: Bloom Night Club | C28: 1035 | D28: 4.8 | E28: 100 Yên Bái | F28: Hai Chau, Da Nang | G28: Beer club | H28: https://www.google.com/maps/search/?api=1&query=Bloom%20Night%20Club&query_place_id=ChIJvV-OKAYZQjER5Q7O4dZyijw | I28: 1522
A29: Nhóm 11 | B29: BÁNH TRÁNG THỊT HEO ĐẠI LỘC - Quán ĐẠI LỘC 97 & 148 Trưng Nữ Vương. | C29: 1035 | D29: 4 | E29: 148 Trưng Nữ Vương | F29: Hải Châu, Đà Nẵng | G29: Quán ăn | H29: https://www.google.com/maps/search/?api=1&query=B%C3%81NH%20TR%C3%81NG%20TH%E1%BB%8AT%20HEO%20%C4%90%E1%BA%A0I%20L%E1%BB%98C%20-%20Qu%C3%A1n%20%C4%90%E1%BA%A0I%20L%E1%BB%98C%2097%20%26%20148%20Tr%C6%B0ng%20N%E1%BB%AF%20V%C6%B0%C6%A1ng.&query_place_id=ChIJkzXqpc4ZQjERZ58aWRvWqGo | I29: 1519
A30: Nhóm 11 | B30: KFC Nguyễn Văn Linh - Đà Nẵng | C30: 1035 | D30: 4.7 | E30: 148 Nguyễn Văn Linh | F30: Hải Châu, Đà Nẵng | G30: Nhà hàng gia đình | H30: https://www.google.com/maps/search/?api=1&query=KFC%20Nguy%E1%BB%85n%20V%C4%83n%20Linh%20-%20%C4%90%C3%A0%20N%E1%BA%B5ng&query_place_id=ChIJv0ja-0gZQjERPPSKulqbzJg | I30: 1518
A31: Nhóm 11 | B31: Bánh tráng thịt heo Quán Cốm Đại Lộc | C31: 699 | D31: 4.7 | E31: 103 Trưng Nữ Vương | F31: Hải Châu, Đà Nẵng | G31: Quán ăn | H31: https://www.google.com/maps/search/?api=1&query=B%C3%A1nh%20tr%C3%A1ng%20th%E1%BB%8Bt%20heo%20Qu%C3%A1n%20C%E1%BB%91m%20%C4%90%E1%BA%A1i%20L%E1%BB%99c&query_place_id=ChIJ2VicQwAZQjERnEOxyC0UA9Q | I31: 699
A32: Nhóm 11 | B32: Xôi Trúc | C32: 56 | D32: 4.8 | E32: 169 Lê Đình Dương | F32: Hai Chau, Da Nang | G32: Quán bar | H32: https://www.google.com/maps/search/?api=1&query=X%C3%B4i%20Tr%C3%BAc&query_place_id=ChIJwXpGWAAZQjERvIf6NVAl4DM | I32: 56
B33: Tổng nhóm | C33: =SUM(C24:C32) -> 8000
A35: Nhóm 14 | B35: DOOKKI GO ĐÀ NẴNG | C35: 1035 | D35: 4.8 | E35: 257 Hùng Vương | F35: Thanh Khe, Da Nang | G35: Quán bar | H35: https://www.google.com/maps/search/?api=1&query=DOOKKI%20GO%20%C4%90%C3%80%20N%E1%BA%B4NG&query_place_id=ChIJa_OfUQAZQjERfQcAUYgli_A | I35: 1386
A36: Nhóm 14 | B36: Alluvia Chocolate 08 Nguyễn Thái Học | C36: 1035 | D36: 5 | E36: 08 Nguyễn Thái Học | F36: Hai Chau, Da Nang | G36: Quán bar | H36: https://www.google.com/maps/search/?api=1&query=Alluvia%20Chocolate%2008%20Nguy%E1%BB%85n%20Th%C3%A1i%20H%E1%BB%8Dc&query_place_id=ChIJLT3SafYZQjERcALeaMTmHOI | I36: 1385
A37: Nhóm 14 | B37: HỦ TIẾU KỲ KỲ - HOÀNG VĂN THỤ | C37: 1035 | D37: 4.8 | E37: 20 Hoàng Văn Thụ | F37: Hải Châu, Đà Nẵng | G37: Quán ăn sáng | H37: https://www.google.com/maps/search/?api=1&query=H%E1%BB%A6%20TI%E1%BA%BEU%20K%E1%BB%B2%20K%E1%BB%B2%20-%20HO%C3%80NG%20V%C4%82N%20TH%E1%BB%A4&query_place_id=ChIJP0cRPt8ZQjERiwv4uPn9nU8 | I37: 1369
A38: Nhóm 14 | B38: Sanuki Udon-Mì Ngon Chuẩn Nhật | C38: 1035 | D38: 4.9 | E38: 135 Nguyễn Văn Linh | F38: Hải Châu, Đà Nẵng | G38: Nhà hàng Nhật Bản | H38: https://www.google.com/maps/search/?api=1&query=Sanuki%20Udon-M%C3%AC%20Ngon%20Chu%E1%BA%A9n%20Nh%E1%BA%ADt&query_place_id=ChIJV4JI6XQZQjERmVWu8gpEqTQ | I38: 1353
A39: Nhóm 14 | B39: Lẩu Bò Triều Châu WangHeNiu Đà Nẵng - 旺和牛潮汕牛肉火锅 (岘港） | C39: 1035 | D39: 4.7 | E39: 24 Pasteur | F39: Hải Châu, Đà Nẵng | G39: Quán ăn tối | H39: https://www.google.com/maps/search/?api=1&query=L%E1%BA%A9u%20B%C3%B2%20Tri%E1%BB%81u%20Ch%C3%A2u%20WangHeNiu%20%C4%90%C3%A0%20N%E1%BA%B5ng%20-%20%E6%97%BA%E5%92%8C%E7%89%9B%E6%BD%AE%E6%B1%95%E7%89%9B%E8%82%89%E7%81%AB%E9%94%85%20(%E5%B2%98%E6%B8%AF%EF%BC%89&query_place_id=ChIJpdc2oT0ZQjERQck5OlhxA7s | I39: 1341
A40: Nhóm 14 | B40: Shin Sushi | C40: 1035 | D40: 4.8 | E40: 69 Thái Phiên | F40: Hải Châu, Đà Nẵng | G40: Quán ăn tối | H40: https://www.google.com/maps/search/?api=1&query=Shin%20Sushi&query_place_id=ChIJYbH5FXIZQjERYn7Pdr11FP4 | I40: 1308
A41: Nhóm 14 | B41: 켓 바 1 Kết Bar | C41: 1035 | D41: 4.9 | E41: 04 Phan Kế Bính | F41: Hai Chau, Da Nang | G41: Lounge bar | H41: https://www.google.com/maps/search/?api=1&query=%EC%BC%93%20%EB%B0%94%201%20K%E1%BA%BFt%20Bar&query_place_id=ChIJu9GUjOgZQjERpfx8z-GIMEw | I41: 1308
A42: Nhóm 14 | B42: Beer Hub - Nhà Hàng Bia Tươi Đức | C42: 693 | D42: 4.3 | E42: 79 nguyễn văn linh,phường phước ninh, 79 Nguyễn Văn Linh | F42: Hai Chau, Da Nang | G42: Beer club | H42: https://www.google.com/maps/search/?api=1&query=Beer%20Hub%20-%20Nh%C3%A0%20H%C3%A0ng%20Bia%20T%C6%B0%C6%A1i%20%C4%90%E1%BB%A9c&query_place_id=ChIJj4MCsjIZQjERRnZtquFLfmY | I42: 693
A43: Nhóm 14 | B43: Bánh canh cá lóc TƠ | C43: 62 | D43: 4 | E43: 140 Lê Đình Dương | F43: Hải Châu, Đà Nẵng | G43: restaurant | H43: https://www.google.com/maps/search/?api=1&query=B%C3%A1nh%20canh%20c%C3%A1%20l%C3%B3c%20T%C6%A0&query_place_id=ChIJpZMpDssZQjERHX2XG82Yf3U | I43: 62
...

Sheet Hiếu
A1: Nhóm | B1: title | C1: reviewsCount (max 1035) | D1: totalScore | E1: street | F1: state | G1: searchString | H1: url | I1: reviewsCount gốc
A2: Nhóm 4 | B2: Yen Yakiniku & Izakaya – Buffet Nướng Nhật Bản tại Đà Nẵng 38 Trần Quốc Toản | C2: 1035 | D2: 4.8 | E2: 38 Trần Quốc Toản | F2: Hai Chau, Da Nang | G2: Quán nhậu | H2: https://www.google.com/maps/search/?api=1&query=Yen%20Yakiniku%20%26%20Izakaya%20%E2%80%93%20Buffet%20N%C6%B0%E1%BB%9Bng%20Nh%E1%BA%ADt%20B%E1%BA%A3n%20t%E1%BA%A1i%20%C4%90%C3%A0%20N%E1%BA%B5ng%2038%20Tr%E1%BA%A7n%20Qu%E1%BB%91c%20To%E1%BA%A3n&query_place_id=ChIJZSsvT9QZQjERf-oLnsT1C3Y | I2: 3543
A3: Nhóm 4 | B3: Mì Quảng Ếch bếp Trang | C3: 1035 | D3: 4.4 | E3: 441 Ông Ích Khiêm | F3: Hải Châu, Đà Nẵng | G3: Quán mỳ | H3: https://www.google.com/maps/search/?api=1&query=M%C3%AC%20Qu%E1%BA%A3ng%20%E1%BA%BEch%20b%E1%BA%BFp%20Trang&query_place_id=ChIJHRmt7soZQjERhuei1xWj9Xs | I3: 3250
A4: Nhóm 4 | B4: Ơ Kìa - Seafood Restaurant | C4: 1035 | D4: 4.8 | E4: 7 Trần Phú | F4: Hai Chau, Da Nang | G4: Pub | H4: https://www.google.com/maps/search/?api=1&query=%C6%A0%20K%C3%ACa%20-%20Seafood%20Restaurant&query_place_id=ChIJfb2A754ZQjERwntwhqY2_nQ | I4: 3201
A5: Nhóm 4 | B5: McDonald's Nguyễn Văn Linh | C5: 1035 | D5: 4.6 | E5: Nguyễn Văn Linh | F5: Hải Châu, Đà Nẵng | G5: restaurant | H5: https://www.google.com/maps/search/?api=1&query=McDonald's%20Nguy%E1%BB%85n%20V%C4%83n%20Linh&query_place_id=ChIJwfmizD8ZQjERtLtHJBCmCDw | I5: 3199
A6: Nhóm 4 | B6: Sky36 Bar Da Nang | C6: 1035 | D6: 4.3 | E6: 34-36 Bạch Đằng | F6: Hai Chau, Da Nang | G6: Rooftop bar | H6: https://www.google.com/maps/search/?api=1&query=Sky36%20Bar%20Da%20Nang&query_place_id=ChIJFWBN5ToYQjERomaB5cZoEaY | I6: 3190
A7: Nhóm 4 | B7: CHÚ BI quán nướng | C7: 1035 | D7: 4.8 | E7: 48 Nguyễn Chí Thanh | F7: Hải Châu, Đà Nẵng | G7: Nhà hàng buffet | H7: https://www.google.com/maps/search/?api=1&query=CH%C3%9A%20BI%20qu%C3%A1n%20n%C6%B0%E1%BB%9Bng&query_place_id=ChIJNcPfRBYZQjERUk2d0LOhtrk | I7: 2961
A8: Nhóm 4 | B8: Phở Bắc Hải | C8: 1035 | D8: 4.3 | E8: 185 Trần Phú | F8: Hai Chau, Da Nang | G8: Wine bar | H8: https://www.google.com/maps/search/?api=1&query=Ph%E1%BB%9F%20B%E1%BA%AFc%20H%E1%BA%A3i&query_place_id=ChIJaRNc9zIYQjER-4clHGRQQZE | I8: 2950
A9: Nhóm 4 | B9: Hoa Lan Souvenir and Coffee Shop | C9: 731 | D9: 5 | E9: 260 Trần Phú | F9: Hai Chau, Da Nang | G9: Coffee shop | H9: https://www.google.com/maps/search/?api=1&query=Hoa%20Lan%20Souvenir%20and%20Coffee%20Shop&query_place_id=ChIJ4wFQqQIZQjERQ29Ifqzv7-k | I9: 731
A10: Nhóm 4 | B10: Jolie coffee & Tea | C10: 24 | D10: 3.5 | E10: 308 Đống Đa | F10: Hai Chau, Da Nang | G10: Coffee | H10: https://www.google.com/maps/search/?api=1&query=Jolie%20coffee%20%26%20Tea&query_place_id=ChIJM_JVflQZQjER1u0IN6tc70s | I10: 24
B11: Tổng nhóm | C11: =SUM(C2:C10) -> 8000
A13: Nhóm 5 | B13: Kaldi & More Coffee Shop | C13: 1035 | D13: 4.7 | E13: 29-31 Hùng Vương | F13: Hai Chau, Da Nang | G13: Coffee | H13: https://www.google.com/maps/search/?api=1&query=Kaldi%20%26%20More%20Coffee%20Shop&query_place_id=ChIJwX-lhoARQjERHzmrwtbKRns | I13: 2917
A14: Nhóm 5 | B14: Cardi Pizzeria Bạch Đằng: Premium Steak & Pizza | C14: 1035 | D14: 4.8 | E14: 124 Bạch Đằng | F14: Hai Chau, Da Nang | G14: Quán pizza | H14: https://www.google.com/maps/search/?api=1&query=Cardi%20Pizzeria%20B%E1%BA%A1ch%20%C4%90%E1%BA%B1ng%3A%20Premium%20Steak%20%26%20Pizza&query_place_id=ChIJnzTGGJMZQjER5GQkGX-COKg | I14: 2659
A15: Nhóm 5 | B15: Gypsy Rooftop Restaurant & Bar | C15: 1035 | D15: 4.9 | E15: 20 Đống Đa | F15: Hai Chau, Da Nang | G15: Beer club | H15: https://www.google.com/maps/search/?api=1&query=Gypsy%20Rooftop%20Restaurant%20%26%20Bar&query_place_id=ChIJ76XtSwwZQjERJapWgs-OVhQ | I15: 2586
A16: Nhóm 5 | B16: Nhà hàng Nhà Gỗ Việt Đà Nẵng | C16: 1035 | D16: 4.6 | E16: 49 Nguyễn Thái Học | F16: Hải Châu, Đà Nẵng | G16: Nhà hàng Việt Nam | H16: https://www.google.com/maps/search/?api=1&query=Nh%C3%A0%20h%C3%A0ng%20Nh%C3%A0%20G%E1%BB%97%20Vi%E1%BB%87t%20%C4%90%C3%A0%20N%E1%BA%B5ng&query_place_id=ChIJYytdRW4ZQjER6149Azrswq8 | I16: 2585
A17: Nhóm 5 | B17: Umi Izakaya | C17: 1035 | D17: 4.7 | E17: 91 Hoàng Văn Thụ | F17: Hai Chau, Da Nang | G17: Quán bar | H17: https://www.google.com/maps/search/?api=1&query=Umi%20Izakaya&query_place_id=ChIJtQe0gqIZQjERwOyKwcOpNqA | I17: 2520
A18: Nhóm 5 | B18: Devis bakery | C18: 1035 | D18: 5 | E18: 60 Nguyễn Thái Học | F18: Hai Chau, Da Nang | G18: Tiệm bánh | H18: https://www.google.com/maps/search/?api=1&query=Devis%20bakery&query_place_id=ChIJ7xQxgxgZQjER9pYz4UOV0EY | I18: 2381
A19: Nhóm 5 | B19: Thai Market Restaurant - Yên Bái | C19: 1035 | D19: 4.4 | E19: 124 Yên Bái | F19: Hải Châu, Đà Nẵng | G19: Quán ăn tối | H19: https://www.google.com/maps/search/?api=1&query=Thai%20Market%20Restaurant%20-%20Y%C3%AAn%20B%C3%A1i&query_place_id=ChIJ6_TBIzMYQjER41Feg1SiLVY | I19: 2319
A20: Nhóm 5 | B20: IKIGAI . garden . cafe | C20: 726 | D20: 4.2 | E20: 60 Nguyễn Chí Thanh | F20: Hai Chau, Da Nang | G20: Quán sinh tố | H20: https://www.google.com/maps/search/?api=1&query=IKIGAI%20.%20garden%20.%20cafe&query_place_id=ChIJedpeSI4ZQjERYqZQdHBbz5E | I20: 726
A21: Nhóm 5 | B21: Cá Nục Cuốn Rau Muống | C21: 29 | D21: 2.8 | E21: 118 Huỳnh Thúc Kháng | F21: Hải Châu, Đà Nẵng | G21: Nhà hàng Việt Nam | H21: https://www.google.com/maps/search/?api=1&query=C%C3%A1%20N%E1%BB%A5c%20Cu%E1%BB%91n%20Rau%20Mu%E1%BB%91ng&query_place_id=ChIJnTjW3ssZQjEROc1qHIzL2xc | I21: 29
B22: Tổng nhóm | C22: =SUM(C13:C21) -> 8000
A24: Nhóm 12 | B24: The Joy Cafe | C24: 1035 | D24: 4.9 | E24: 7 Nguyễn Thái Học | F24: Hai Chau, Da Nang | G24: Cafe | H24: https://www.google.com/maps/search/?api=1&query=The%20Joy%20Cafe&query_place_id=ChIJl6bSFKAZQjERDdamCBNpBig | I24: 1511
A25: Nhóm 12 | B25: Xuyên Sushi - Đà Nẵng Cơ Sở 1 | C25: 1035 | D25: 4.7 | E25: Phan Châu Trinh/329A Bình Hiên | F25: Hải Châu, Đà Nẵng | G25: restaurant | H25: https://www.google.com/maps/search/?api=1&query=Xuy%C3%AAn%20Sushi%20-%20%C4%90%C3%A0%20N%E1%BA%B5ng%20C%C6%A1%20S%E1%BB%9F%201&query_place_id=ChIJD2KF7jEZQjERFNLDyHE50X8 | I25: 1507
A26: Nhóm 12 | B26: Nhà Hàng Chay Ngọc Chi - Vegetarian Restaurant Michelin guide 2025 | C26: 1035 | D26: 4.6 | E26: 202 Hoàng Diệu | F26: Hai Chau, Da Nang | G26: Pub | H26: https://www.google.com/maps/search/?api=1&query=Nh%C3%A0%20H%C3%A0ng%20Chay%20Ng%E1%BB%8Dc%20Chi%20-%20Vegetarian%20Restaurant%20Michelin%20guide%202025&query_place_id=ChIJPwlvPjMYQjERE56T1OCbYpM | I26: 1498
A27: Nhóm 12 | B27: LUNA Pub | C27: 1035 | D27: 4.4 | E27: 9A Trần Phú | F27: Hai Chau, Da Nang | G27: Wine bar | H27: https://www.google.com/maps/search/?api=1&query=LUNA%20Pub&query_place_id=ChIJ_5cPdjsYQjERLVVya-SBx24 | I27: 1497
A28: Nhóm 12 | B28: Highlands Coffee Hoang Anh Gia Lai | C28: 1035 | D28: 4.2 | E28: 115 Nguyễn Văn Linh | F28: Hải Châu, Đà Nẵng | G28: Quán ăn sáng | H28: https://www.google.com/maps/search/?api=1&query=Highlands%20Coffee%20Hoang%20Anh%20Gia%20Lai&query_place_id=ChIJ4ZJeS8oZQjERzAlK2SZaZaA | I28: 1492
A29: Nhóm 12 | B29: Chè Xuân Trang - cs 1 | C29: 1035 | D29: 4.1 | E29: 31 Lê Duẩn | F29: Hai Chau, Da Nang | G29: Quán chè | H29: https://www.google.com/maps/search/?api=1&query=Che%CC%80%20Xu%C3%A2n%20Trang%20-%20cs%201&query_place_id=ChIJ--T9ODEYQjERsbP55nVTym0 | I29: 1478
A30: Nhóm 12 | B30: Quán Phú Hồng | C30: 1035 | D30: 4.8 | E30: 19 Yên Bái | F30: Hải Châu, Đà Nẵng | G30: Quán ăn tối | H30: https://www.google.com/maps/search/?api=1&query=Qu%C3%A1n%20Phu%CC%81%20H%C3%B4%CC%80ng&query_place_id=ChIJ3xzmKjIYQjERKrkpxfu1R-Y | I30: 1478
A31: Nhóm 12 | B31: Trạm Ốc | C31: 694 | D31: 4.9 | E31: Hoàng Diệu/338/14 Bình Hiên | F31: Hai Chau, Da Nang | G31: Quán bar | H31: https://www.google.com/maps/search/?api=1&query=Tr%E1%BA%A1m%20%E1%BB%90c&query_place_id=ChIJCRvUiqYZQjERhzBUP7NWgmk | I31: 694
A32: Nhóm 12 | B32: Mì Tiều Châu | C32: 61 | D32: 4.6 | E32: 81 Thái Phiên | F32: Hải Châu, Đà Nẵng | G32: Nhà hàng Trung Quốc | H32: https://www.google.com/maps/search/?api=1&query=M%C3%AC%20Ti%E1%BB%81u%20Ch%C3%A2u&query_place_id=ChIJ-xCOTAAZQjERx4KPuNm76uw | I32: 61
B33: Tổng nhóm | C33: =SUM(C24:C32) -> 8000
A35: Nhóm 13 | B35: PER Korean food 2 | C35: 1035 | D35: 4.8 | E35: 204 Trần Phú | F35: Hải Châu, Đà Nẵng | G35: Quán ăn tối | H35: https://www.google.com/maps/search/?api=1&query=PER%20Korean%20food%202&query_place_id=ChIJ5auxl7QZQjER-3drr1-un8I | I35: 1465
A36: Nhóm 13 | B36: Phê La - Nguyễn Văn Linh, Đà Nẵng | C36: 1035 | D36: 4.3 | E36: 35 - 41 Nguyễn Văn Linh | F36: Hai Chau, Da Nang | G36: Cửa hàng bánh ngọt | H36: https://www.google.com/maps/search/?api=1&query=Ph%C3%AA%20La%20-%20Nguy%C3%AA%CC%83n%20V%C4%83n%20Linh%2C%20%C4%90%C3%A0%20N%E1%BA%B5ng&query_place_id=ChIJt5mYvvwZQjERec2rBUXL57A | I36: 1443
A37: Nhóm 13 | B37: Chè Liên Desserts | C37: 1035 | D37: 4.1 | E37: 175 Hải Phòng | F37: Thanh Khe, Da Nang | G37: Quán chè | H37: https://www.google.com/maps/search/?api=1&query=Ch%C3%A8%20Li%C3%AAn%20Desserts&query_place_id=ChIJJRvF6kkYQjERxtXYO1fCZCY | I37: 1434
A38: Nhóm 13 | B38: Bikini Bottom Express Pink Church | C38: 1035 | D38: 4.7 | E38: 154 Trần Phú | F38: Hải Châu, Đà Nẵng | G38: restaurant | H38: https://www.google.com/maps/search/?api=1&query=Bikini%20Bottom%20Express%20Pink%20Church&query_place_id=ChIJ7Qa_GAAZQjERwDheIFSvF2c | I38: 1424
A39: Nhóm 13 | B39: KOI Thé Nguyễn Văn Linh | C39: 1035 | D39: 4.5 | E39: 87 Nguyễn Văn Linh | F39: Hai Chau, Da Nang | G39: Trà sữa | H39: https://www.google.com/maps/search/?api=1&query=KOI%20Th%C3%A9%20Nguy%E1%BB%85n%20V%C4%83n%20Linh&query_place_id=ChIJz9j72agZQjERNYhRtw1ahGo | I39: 1414
A40: Nhóm 13 | B40: PhiPhi Sushi | C40: 1035 | D40: 4.7 | E40: 41 Lê Hồng Phong | F40: Hai Chau, Da Nang | G40: Quán nhậu | H40: https://www.google.com/maps/search/?api=1&query=PhiPhi%20Sushi&query_place_id=ChIJcQ0Qs0kYQjERDxit3A23Ggc | I40: 1402
A41: Nhóm 13 | B41: BOK JJAM PPONG | C41: 1035 | D41: 4.8 | E41: 92a Trần Phú | F41: Hải Châu, Đà Nẵng | G41: Nhà hàng Hàn Quốc | H41: https://www.google.com/maps/search/?api=1&query=BOK%20JJAM%20PPONG&query_place_id=ChIJDWu4c_MZQjEREd-mkCKxnU4 | I41: 1393
A42: Nhóm 13 | B42: Bánh Mì Kim | C42: 694 | D42: 4.8 | E42: 16/4 Hùng Vương | F42: Hai Chau, Da Nang | G42: Bánh mỳ | H42: https://www.google.com/maps/search/?api=1&query=B%C3%A1nh%20M%C3%AC%20Kim&query_place_id=ChIJ35a1SGUZQjER2T5aqZ-6vjU | I42: 694
A43: Nhóm 13 | B43: Tiệm ăn Luckki | C43: 61 | D43: 3.7 | E43: 206/5 Đống Đa | F43: Hai Chau, Da Nang | G43: Quán nhậu | H43: https://www.google.com/maps/search/?api=1&query=Ti%E1%BB%87m%20%C4%83n%20Luckki&query_place_id=ChIJ3a_cwWkZQjERo4bs9gHuIpg | I43: 61
...

Sheet Tổng hợp
A1: Người | B1: Nhóm / acc | C1: Số địa điểm | D1: Tổng reviewsCount
A2: Người 1 | B2: Nhóm 1 | C2: 9 | D2: ='Người 1'!C11 -> 8000
A3: Người 1 | B3: Nhóm 8 | C3: 9 | D3: ='Người 1'!C22 -> 8000
A4: Người 1 | B4: Nhóm 9 | C4: 9 | D4: ='Người 1'!C33 -> 8000
A5: Người 1 | B5: Nhóm 16 | C5: 9 | D5: ='Người 1'!C44 -> 8000
A6: Người 1 | B6: Nhóm 17 | C6: 9 | D6: ='Người 1'!C55 -> 8000
A7: Người 1 | B7: Nhóm 24 | C7: 14 | D7: ='Người 1'!C71 -> 8000
A8: Người 1 | B8: Nhóm 25 | C8: 14 | D8: ='Người 1'!C87 -> 8000
A9: Người 1 | B9: Nhóm 32 | C9: 28 | D9: ='Người 1'!C117 -> 8000
A10: Người 1 | B10: Nhóm 33 | C10: 32 | D10: ='Người 1'!C151 -> 8000
A11: Người 1 | B11: Nhóm 40 | C11: 738 | D11: ='Người 1'!C891 -> 7764
A12: Người 2 | B12: Nhóm 2 | C12: 9 | D12: ='Trân'!C11 -> 8000
A13: Người 2 | B13: Nhóm 7 | C13: 9 | D13: ='Trân'!C22 -> 8000
A14: Người 2 | B14: Nhóm 10 | C14: 9 | D14: ='Trân'!C33 -> 8000
A15: Người 2 | B15: Nhóm 15 | C15: 9 | D15: ='Trân'!C44 -> 8000
A16: Người 2 | B16: Nhóm 18 | C16: 9 | D16: ='Trân'!C55 -> 8000
A17: Người 2 | B17: Nhóm 23 | C17: 13 | D17: ='Trân'!C70 -> 8000
A18: Người 2 | B18: Nhóm 26 | C18: 16 | D18: ='Trân'!C88 -> 8000
A19: Người 2 | B19: Nhóm 31 | C19: 24 | D19: ='Trân'!C114 -> 8000
A20: Người 2 | B20: Nhóm 34 | C20: 37 | D20: ='Trân'!C153 -> 8000
A21: Người 2 | B21: Nhóm 39 | C21: 152 | D21: ='Trân'!C307 -> 8000
A22: Người 3 | B22: Nhóm 3 | C22: 9 | D22: ='Nguyên'!C11 -> 8000
A23: Người 3 | B23: Nhóm 6 | C23: 9 | D23: ='Nguyên'!C22 -> 8000
A24: Người 3 | B24: Nhóm 11 | C24: 9 | D24: ='Nguyên'!C33 -> 8000
A25: Người 3 | B25: Nhóm 14 | C25: 9 | D25: ='Nguyên'!C44 -> 8000
A26: Người 3 | B26: Nhóm 19 | C26: 9 | D26: ='Nguyên'!C55 -> 8000
A27: Người 3 | B27: Nhóm 22 | C27: 11 | D27: ='Nguyên'!C68 -> 8000
A28: Người 3 | B28: Nhóm 27 | C28: 16 | D28: ='Nguyên'!C86 -> 8000
A29: Người 3 | B29: Nhóm 30 | C29: 22 | D29: ='Nguyên'!C110 -> 8000
A30: Người 3 | B30: Nhóm 35 | C30: 44 | D30: ='Nguyên'!C156 -> 8000
A31: Người 3 | B31: Nhóm 38 | C31: 94 | D31: ='Nguyên'!C252 -> 8000
A32: Người 4 | B32: Nhóm 4 | C32: 9 | D32: ='Hiếu'!C11 -> 8000
A33: Người 4 | B33: Nhóm 5 | C33: 9 | D33: ='Hiếu'!C22 -> 8000
A34: Người 4 | B34: Nhóm 12 | C34: 9 | D34: ='Hiếu'!C33 -> 8000
A35: Người 4 | B35: Nhóm 13 | C35: 9 | D35: ='Hiếu'!C44 -> 8000
A36: Người 4 | B36: Nhóm 20 | C36: 9 | D36: ='Hiếu'!C55 -> 8000
A37: Người 4 | B37: Nhóm 21 | C37: 11 | D37: ='Hiếu'!C68 -> 8000
A38: Người 4 | B38: Nhóm 28 | C38: 18 | D38: ='Hiếu'!C88 -> 8000
A39: Người 4 | B39: Nhóm 29 | C39: 19 | D39: ='Hiếu'!C109 -> 8000
A40: Người 4 | B40: Nhóm 36 | C40: 53 | D40: ='Hiếu'!C164 -> 8000
...
